Workbook
Name _____xlnm._FilterDatabase: #REF!
Name Print_Titles: #REF!
Name _____xlnm.Print_Titles_1: #REF!
Name ____xlnm._FilterDatabase: #REF!
Name ____xlnm.Print_Titles_1: #REF!
Name ___xlnm._FilterDatabase: #REF!
Name ___xlnm.Print_Titles_1: #REF!
Name __xlnm._FilterDatabase: #REF!
Name __xlnm.Print_Titles_1: #REF!
Name _bce2004: #REF!
Name _BCE2005: #REF!
Name _DAT1: #REF!
Name _DAT10: #REF!
Name _DAT2: #REF!
Name _DAT3: #REF!
Name _DAT4: #REF!
Name _DAT5: #REF!
Name _DAT6: #REF!
Name _DAT7: #REF!
Name _DAT8: #REF!
Name _DAT9: #REF!
Name _sys2005: #REF!
Name a: #REF!
Name AA: #REF!
Name ACT_FIJOS_VALOR: #REF!
Name AJUSTE_REAJ_FIS_AF: #REF!
Name anexo: #REF!
Name anexo04: #REF!
Name Print_Area: #REF!
Name asd: #REF!
Name BSH: #REF!
Name BuiltIn_Print_Area: #REF!
Name BuiltIn_Print_Area___0: #REF!
Name BVAN: #REF!
Name CALDECNM: #REF!
Name Caracter: #REF!
Name CIIU: #REF!
Name CIIUNM: #REF!
Name Citibank: #REF!
Name CLASEDEC: #REF!
Name CLASEDECNM: #REF!
Name COBRANZAS: #REF!
Name CODADMONNM: #REF!
Name CODDOCSNM: #REF!
Name CUENTAS: #REF!
Name DEPTOSNM: #REF!
Name dimension: #REF!
Name DIVIPOL: #REF!
Name DIVIPOL1: #REF!
Name DIVIPOLCOD: #REF!
Name DIVIPOLNM: #REF!
Name Excel_BuiltIn_Print_Titles: #REF!
Name Excel_BuiltIn_Print_Titles_1: #REF!
Name FACTURAS: #REF!
Name G: #REF!
Name gActEcono: #REF!
Name gAdmon: #REF!
Name gAño: #REF!
Name gApe1Dec: #REF!
Name gApe1Rev: #REF!

Sheet Cartera
A1: Cuenta contable | B1: Denominación cuenta contable | C1: Emisor | D1: Tipo | E1: Estado | F1: Grupo | G1: Casa de bolsa | H1: Serie | I1: Fecha Compra | J1: Fecha Vencimiento Serie | K1: Calificacion de riesgo | L1: Instrumento | M1: Tasa Interes | N1: Referencia Tasa | O1: Moneda | P1: Importe Valorizado | Q1: Valor actual en PYG | R1: Valor actual en USD | S1: Estado de cupon / Capital | T1: Comitente | U1: Capital | V1: Intereses | W1: No. Cupón | X1: % Amortizacion | Y1: Amortizacion de capital | Z1: Consolidado | AA1: Titulos Colocados | AB1: Total | AC1: Instrumento | AD1: Instrumento 3 | AE1: Mes Vto | AF1: Año Vto | AG1: Observaciones
A2: 12303 | B2: Acciones en Otras Empresas LP - PYG | C2: SUDAMERIS BANK S.A.E.C.A. | D2: Capital | E2: Activo | F2: Grupo Sudameris | H2: Acciones Ordinarias "A" | I2: 43581 | J2: No aplica | Acciones | K2: AA+py Estable | L2: Acciones | M2: 0.07 | N2: =IF(AND(M2>#REF!,Cartera!O2="Guaraníes"),"Rendimiento significativo",IF(AND(M2>#REF!,Cartera!O2="Dólares americanos"),"Rendimiento significativo","Rendimiento no significativo")) -> #REF! | O2: Guaraníes | P2: 3100000 | Q2: =IF(O2="Guaraníes",P2,P2*#REF!) -> 3100000 | R2: =IF(O2="Guaraníes",P2/#REF!,P2) -> #REF! | S2: Pendiente | AC2: =IF(ISNUMBER(SEARCH("Acciones",L2)),"Acciones",IF(ISNUMBER(SEARCH("Bono",L2)),"Bonos",IF(ISNUMBER(SEARCH("CDA",L2)),"CDA",IF(ISNUMBER(SEARCH("Fondo",L2)),"Fondo",0)))) -> Acciones | AD2: Otros | AE2: =IFERROR((MONTH(J2)),0) -> 0 | AF2: =IFERROR((YEAR(J2)),0) -> 0
A3: Vencido | Cobrado | B3: Vencido | Cobrado | C3: BANCO BASA S.A. | D3: Intereses | E3: Vencido | Cobrado | F3: Grupo Cartes | G3: CAPITAL MARKETS CBSA | H3: PYBAM01F9268 | J3: 44767 | K3: AA-py Estable | L3: Bonos Subordinados | M3: 0.0525 | N3: =IF(AND(M3>#REF!,Cartera!O3="Guaraníes"),"Rendimiento significativo",IF(AND(M3>#REF!,Cartera!O3="Dólares americanos"),"Rendimiento significativo","Rendimiento no significativo")) -> #REF! | O3: Dólares americanos | P3: 174.52055 | Q3: =IF(O3="Guaraníes",P3,P3*#REF!) -> #REF! | R3: =IF(O3="Guaraníes",P3/#REF!,P3) -> 174.52055 | S3: Acreditado | T3: 4 | W3: 1/24 | X3: 0 | Y3: 0 | Z3: 17.452055 | AA3: 10 | AB3: 174.52055 | AC3: =IF(ISNUMBER(SEARCH("Acciones",L3)),"Acciones",IF(ISNUMBER(SEARCH("Bono",L3)),"Bonos",IF(ISNUMBER(SEARCH("CDA",L3)),"CDA",IF(ISNUMBER(SEARCH("Fondo",L3)),"Fondo",0)))) -> Bonos | AD3: Otros | AE3: =IFERROR((MONTH(J3)),0) -> 7 | AF3: =IFERROR((YEAR(J3)),0) -> 2022
A4: Vencido | Cobrado | B4: Vencido | Cobrado | C4: CEMENTOS CONCEPCIÓN SOCIEDAD ANÓNIMA EMISORA | D4: Intereses | E4: Vencido | Cobrado | F4: Grupo Cartes | G4: ASU CAPITAL CBSA | H4: PYCEC01F3409 | I4: 44680 | J4: 44771 | K4: pyAA- Estable | L4: Bonos | M4: 0.06 | N4: =IF(AND(M4>#REF!,Cartera!O4="Guaraníes"),"Rendimiento significativo",IF(AND(M4>#REF!,Cartera!O4="Dólares americanos"),"Rendimiento significativo","Rendimiento no significativo")) -> #REF! | O4: Dólares americanos | P4: 747.95 | Q4: =IF(O4="Guaraníes",P4,P4*#REF!) -> #REF! | R4: =IF(O4="Guaraníes",P4/#REF!,P4) -> 747.95 | S4: Acreditado | T4: 17035 | V4: 14.96 | AA4: 50 | AC4: =IF(ISNUMBER(SEARCH("Acciones",L4)),"Acciones",IF(ISNUMBER(SEARCH("Bono",L4)),"Bonos",IF(ISNUMBER(SEARCH("CDA",L4)),"CDA",IF(ISNUMBER(SEARCH("Fondo",L4)),"Fondo",0)))) -> Bonos | AD4: Otros | AE4: =IFERROR((MONTH(J4)),0) -> 7 | AF4: =IFERROR((YEAR(J4)),0) -> 2022
A5: Vencido | Cobrado | B5: Vencido | Cobrado | C5: CEMENTOS CONCEPCIÓN SOCIEDAD ANÓNIMA EMISORA | D5: Intereses | E5: Vencido | Cobrado | F5: Grupo Cartes | G5: ASU CAPITAL CBSA | H5: PYCEC01F3409 | I5: 44680 | J5: 44862 | K5: pyAA- Estable | L5: Bonos | M5: 0.06 | N5: =IF(AND(M5>#REF!,Cartera!O5="Guaraníes"),"Rendimiento significativo",IF(AND(M5>#REF!,Cartera!O5="Dólares americanos"),"Rendimiento significativo","Rendimiento no significativo")) -> #REF! | O5: Dólares americanos | P5: 747.95 | Q5: =IF(O5="Guaraníes",P5,P5*#REF!) -> #REF! | R5: =IF(O5="Guaraníes",P5/#REF!,P5) -> 747.95 | S5: Acreditado | T5: 17035 | V5: 14.96 | AA5: 50 | AC5: =IF(ISNUMBER(SEARCH("Acciones",L5)),"Acciones",IF(ISNUMBER(SEARCH("Bono",L5)),"Bonos",IF(ISNUMBER(SEARCH("CDA",L5)),"CDA",IF(ISNUMBER(SEARCH("Fondo",L5)),"Fondo",0)))) -> Bonos | AD5: Otros | AE5: =IFERROR((MONTH(J5)),0) -> 10 | AF5: =IFERROR((YEAR(J5)),0) -> 2022
A6: Vencido | Cobrado | B6: Vencido | Cobrado | C6: CEMENTOS CONCEPCIÓN SOCIEDAD ANÓNIMA EMISORA | D6: Intereses | E6: Vencido | Cobrado | F6: Grupo Cartes | G6: ASU CAPITAL CBSA | H6: PYCEC01F3409 | I6: 44680 | J6: 44953 | K6: pyAA- Estable | L6: Bonos | M6: 0.06 | N6: =IF(AND(M6>#REF!,Cartera!O6="Guaraníes"),"Rendimiento significativo",IF(AND(M6>#REF!,Cartera!O6="Dólares americanos"),"Rendimiento significativo","Rendimiento no significativo")) -> #REF! | O6: Dólares americanos | P6: 747.95 | Q6: =IF(O6="Guaraníes",P6,P6*#REF!) -> #REF! | R6: =IF(O6="Guaraníes",P6/#REF!,P6) -> 747.95 | S6: Acreditado | T6: 17035 | V6: 14.96 | AA6: 50 | AC6: =IF(ISNUMBER(SEARCH("Acciones",L6)),"Acciones",IF(ISNUMBER(SEARCH("Bono",L6)),"Bonos",IF(ISNUMBER(SEARCH("CDA",L6)),"CDA",IF(ISNUMBER(SEARCH("Fondo",L6)),"Fondo",0)))) -> Bonos | AD6: Otros | AE6: =IFERROR((MONTH(J6)),0) -> 1 | AF6: =IFERROR((YEAR(J6)),0) -> 2023
A7: Vencido | Cobrado | B7: Vencido | Cobrado | C7: CEMENTOS CONCEPCIÓN SOCIEDAD ANÓNIMA EMISORA | D7: Intereses | E7: Vencido | Cobrado | F7: Grupo Cartes | G7: ASU CAPITAL CBSA | H7: PYCEC01F3409 | I7: 44680 | J7: 45044 | K7: pyAA- Estable | L7: Bonos | M7: 0.06 | N7: =IF(AND(M7>#REF!,Cartera!O7="Guaraníes"),"Rendimiento significativo",IF(AND(M7>#REF!,Cartera!O7="Dólares americanos"),"Rendimiento significativo","Rendimiento no significativo")) -> #REF! | O7: Dólares americanos | P7: 747.95 | Q7: =IF(O7="Guaraníes",P7,P7*#REF!) -> #REF! | R7: =IF(O7="Guaraníes",P7/#REF!,P7) -> 747.95 | S7: Acreditado | T7: 17035 | V7: 14.96 | AA7: 50 | AC7: =IF(ISNUMBER(SEARCH("Acciones",L7)),"Acciones",IF(ISNUMBER(SEARCH("Bono",L7)),"Bonos",IF(ISNUMBER(SEARCH("CDA",L7)),"CDA",IF(ISNUMBER(SEARCH("Fondo",L7)),"Fondo",0)))) -> Bonos | AD7: Otros | AE7: =IFERROR((MONTH(J7)),0) -> 4 | AF7: =IFERROR((YEAR(J7)),0) -> 2023
A8: Vencido | Cobrado | B8: Vencido | Cobrado | C8: CEMENTOS CONCEPCIÓN SOCIEDAD ANÓNIMA EMISORA | D8: Intereses | E8: Vencido | Cobrado | F8: Grupo Cartes | G8: ASU CAPITAL CBSA | H8: PYCEC01F3409 | I8: 44680 | J8: 45135 | K8: pyAA- Estable | L8: Bonos | M8: 0.06 | N8: =IF(AND(M8>#REF!,Cartera!O8="Guaraníes"),"Rendimiento significativo",IF(AND(M8>#REF!,Cartera!O8="Dólares americanos"),"Rendimiento significativo","Rendimiento no significativo")) -> #REF! | O8: Dólares americanos | P8: 747.95 | Q8: =IF(O8="Guaraníes",P8,P8*#REF!) -> #REF! | R8: =IF(O8="Guaraníes",P8/#REF!,P8) -> 747.95 | S8: Acreditado | T8: 17035 | V8: 14.96 | AA8: 50 | AC8: =IF(ISNUMBER(SEARCH("Acciones",L8)),"Acciones",IF(ISNUMBER(SEARCH("Bono",L8)),"Bonos",IF(ISNUMBER(SEARCH("CDA",L8)),"CDA",IF(ISNUMBER(SEARCH("Fondo",L8)),"Fondo",0)))) -> Bonos | AD8: Otros | AE8: =IFERROR((MONTH(J8)),0) -> 7 | AF8: =IFERROR((YEAR(J8)),0) -> 2023
A9: Vencido | Cobrado | B9: Vencido | Cobrado | C9: CEMENTOS CONCEPCIÓN SOCIEDAD ANÓNIMA EMISORA | D9: Intereses | E9: Vencido | Cobrado | F9: Grupo Cartes | G9: ASU CAPITAL CBSA | H9: PYCEC01F3409 | I9: 44680 | J9: 45226 | K9: pyAA- Estable | L9: Bonos | M9: 0.06 | N9: =IF(AND(M9>#REF!,Cartera!O9="Guaraníes"),"Rendimiento significativo",IF(AND(M9>#REF!,Cartera!O9="Dólares americanos"),"Rendimiento significativo","Rendimiento no significativo")) -> #REF! | O9: Dólares americanos | P9: 747.9452 | Q9: =IF(O9="Guaraníes",P9,P9*#REF!) -> #REF! | R9: =IF(O9="Guaraníes",P9/#REF!,P9) -> 747.9452 | S9: Acreditado | T9: 17035 | V9: 14.96 | AA9: 50 | AC9: =IF(ISNUMBER(SEARCH("Acciones",L9)),"Acciones",IF(ISNUMBER(SEARCH("Bono",L9)),"Bonos",IF(ISNUMBER(SEARCH("CDA",L9)),"CDA",IF(ISNUMBER(SEARCH("Fondo",L9)),"Fondo",0)))) -> Bonos | AD9: Otros | AE9: =IFERROR((MONTH(J9)),0) -> 10 | AF9: =IFERROR((YEAR(J9)),0) -> 2023
A10: Vencido | Cobrado | B10: Vencido | Cobrado | C10: CEMENTOS CONCEPCIÓN SOCIEDAD ANÓNIMA EMISORA | D10: Intereses | E10: Vencido | Cobrado | F10: Grupo Cartes | G10: ASU CAPITAL CBSA | H10: PYCEC01F3409 | I10: 44680 | J10: 45317 | K10: pyAA- Estable | L10: Bonos | M10: 0.06 | N10: =IF(AND(M10>#REF!,Cartera!O10="Guaraníes"),"Rendimiento significativo",IF(AND(M10>#REF!,Cartera!O10="Dólares americanos"),"Rendimiento significativo","Rendimiento no significativo")) -> #REF! | O10: Dólares americanos | P10: 747.9452 | Q10: =IF(O10="Guaraníes",P10,P10*#REF!) -> #REF! | R10: =IF(O10="Guaraníes",P10/#REF!,P10) -> 747.9452 | S10: Acreditado | T10: 17035 | V10: 14.96 | AA10: 50 | AC10: =IF(ISNUMBER(SEARCH("Acciones",L10)),"Acciones",IF(ISNUMBER(SEARCH("Bono",L10)),"Bonos",IF(ISNUMBER(SEARCH("CDA",L10)),"CDA",IF(ISNUMBER(SEARCH("Fondo",L10)),"Fondo",0)))) -> Bonos | AD10: Otros | AE10: =IFERROR((MONTH(J10)),0) -> 1 | AF10: =IFERROR((YEAR(J10)),0) -> 2024
A11: Vencido | Cobrado | B11: Vencido | Cobrado | C11: CEMENTOS CONCEPCIÓN SOCIEDAD ANÓNIMA EMISORA | D11: Intereses | E11: Vencido | Cobrado | F11: Grupo Cartes | G11: ASU CAPITAL CBSA | H11: PYCEC01F3409 | I11: 44680 | J11: 45408 | K11: pyAA- Estable | L11: Bonos | M11: 0.06 | N11: =IF(AND(M11>#REF!,Cartera!O11="Guaraníes"),"Rendimiento significativo",IF(AND(M11>#REF!,Cartera!O11="Dólares americanos"),"Rendimiento significativo","Rendimiento no significativo")) -> #REF! | O11: Dólares americanos | P11: 747.9452 | Q11: =IF(O11="Guaraníes",P11,P11*#REF!) -> #REF! | R11: =IF(O11="Guaraníes",P11/#REF!,P11) -> 747.9452 | S11: Acreditado | T11: 17035 | V11: 14.96 | AA11: 50 | AC11: =IF(ISNUMBER(SEARCH("Acciones",L11)),"Acciones",IF(ISNUMBER(SEARCH("Bono",L11)),"Bonos",IF(ISNUMBER(SEARCH("CDA",L11)),"CDA",IF(ISNUMBER(SEARCH("Fondo",L11)),"Fondo",0)))) -> Bonos | AD11: Otros | AE11: =IFERROR((MONTH(J11)),0) -> 4 | AF11: =IFERROR((YEAR(J11)),0) -> 2024
A12: Vencido | Cobrado | B12: Vencido | Cobrado | C12: CEMENTOS CONCEPCIÓN SOCIEDAD ANÓNIMA EMISORA | D12: Intereses | E12: Vencido | Cobrado | F12: Grupo Cartes | G12: ASU CAPITAL CBSA | H12: PYCEC01F3409 | I12: 44680 | J12: 45499 | K12: pyAA- Estable | L12: Bonos | M12: 0.06 | N12: =IF(AND(M12>#REF!,Cartera!O12="Guaraníes"),"Rendimiento significativo",IF(AND(M12>#REF!,Cartera!O12="Dólares americanos"),"Rendimiento significativo","Rendimiento no significativo")) -> #REF! | O12: Dólares americanos | P12: 747.9452 | Q12: =IF(O12="Guaraníes",P12,P12*#REF!) -> #REF! | R12: =IF(O12="Guaraníes",P12/#REF!,P12) -> 747.9452 | S12: Acreditado | T12: 17035 | V12: 14.96 | AA12: 50 | AC12: =IF(ISNUMBER(SEARCH("Acciones",L12)),"Acciones",IF(ISNUMBER(SEARCH("Bono",L12)),"Bonos",IF(ISNUMBER(SEARCH("CDA",L12)),"CDA",IF(ISNUMBER(SEARCH("Fondo",L12)),"Fondo",0)))) -> Bonos | AD12: Otros | AE12: =IFERROR((MONTH(J12)),0) -> 7 | AF12: =IFERROR((YEAR(J12)),0) -> 2024
A13: 11401 | B13: Intereses Financieros a Cobrar CP - USD | C13: BANCO RIO SAECA | D13: Intereses | E13: Activo | F13: Grupo Continental | G13: AVALON CBSA | H13: PYBRO02F1560 | J13: 45425 | K13: A+py Estable | L13: Bonos Subordinados | M13: 0.0525 | N13: =IF(AND(M13>#REF!,Cartera!O141="Guaraníes"),"Rendimiento significativo",IF(AND(M13>#REF!,Cartera!O141="Dólares americanos"),"Rendimiento significativo","Rendimiento no significativo")) -> #REF! | O13: Dólares americanos | P13: 785.34246 | Q13: =IF(O13="Guaraníes",P13,P13*#REF!) -> #REF! | R13: =IF(O13="Guaraníes",P13/#REF!,P13) -> 785.34246 | S13: Pendiente | T13: 8 | W13: / | X13: 0 | Y13: 0 | Z13: 26.178082 | AA13: 30 | AB13: 785.34246 | AC13: =IF(ISNUMBER(SEARCH("Acciones",L13)),"Acciones",IF(ISNUMBER(SEARCH("Bono",L13)),"Bonos",IF(ISNUMBER(SEARCH("CDA",L13)),"CDA",IF(ISNUMBER(SEARCH("Fondo",L13)),"Fondo",0)))) -> Bonos | AD13: Otros | AE13: =IFERROR((MONTH(J13)),0) -> 5 | AF13: =IFERROR((YEAR(J13)),0) -> 2024 | AG13: Acreditado en cuenta del Fondo de Garantia. Se solicitó devolución a la cuenta 677
A14: Vencido | Cobrado | B14: Vencido | Cobrado | C14: RIEDER & CÍA. S.A.C.I. | D14: Intereses | E14: Vencido | Cobrado | F14: No aplica a grupos | G14: VALORES CBSA | H14: PYRIE03F8098 | J14: 45525 | K14: pyBBB- Estable | L14: Bonos | M14: 0.0675 | N14: =IF(AND(M14>#REF!,Cartera!O2376="Guaraníes"),"Rendimiento significativo",IF(AND(M14>#REF!,Cartera!O2376="Dólares americanos"),"Rendimiento significativo","Rendimiento no significativo")) -> #REF! | O14: Dólares americanos | P14: 49.09 | Q14: =IF(O14="Guaraníes",P14,P14*#REF!) -> #REF! | R14: =IF(O14="Guaraníes",P14/#REF!,P14) -> 49.09 | S14: Acreditado | T14: 593 | W14: 4/43 | X14: 4.1666667 | Y14: 41.666667 | Z14: 47.03653 | AA14: 8 | AB14: 376.29224 | AC14: =IF(ISNUMBER(SEARCH("Acciones",L14)),"Acciones",IF(ISNUMBER(SEARCH("Bono",L14)),"Bonos",IF(ISNUMBER(SEARCH("CDA",L14)),"CDA",IF(ISNUMBER(SEARCH("Fondo",L14)),"Fondo",0)))) -> Bonos | AD14: Otros | AE14: =IFERROR((MONTH(J14)),0) -> 8 | AF14: =IFERROR((YEAR(J14)),0) -> 2024
A15: 12315 | B15: Intereses Financieros a Cobrar LP - USD | C15: SOLAR BANCO S.A.E. | D15: Intereses | E15: Activo | F15: No aplica a grupos | G15: CADIEM CBSA | H15: PYSAF01F1422 | J15: 45659 | K15: Apy Estable | L15: Bonos Subordinados | M15: 0.055 | N15: =IF(AND(M15>#REF!,Cartera!O901="Guaraníes"),"Rendimiento significativo",IF(AND(M15>#REF!,Cartera!O901="Dólares americanos"),"Rendimiento significativo","Rendimiento no significativo")) -> #REF! | O15: Dólares americanos | P15: 420.41097 | Q15: =IF(O15="Guaraníes",P15,P15*#REF!) -> #REF! | R15: =IF(O15="Guaraníes",P15/#REF!,P15) -> 420.41097 | S15: Pendiente | T15: 25 | W15: / | X15: 0 | Y15: 0 | Z15: 14.013699 | AA15: 30 | AB15: 420.41 | AC15: =IF(ISNUMBER(SEARCH("Acciones",L15)),"Acciones",IF(ISNUMBER(SEARCH("Bono",L15)),"Bonos",IF(ISNUMBER(SEARCH("CDA",L15)),"CDA",IF(ISNUMBER(SEARCH("Fondo",L15)),"Fondo",0)))) -> Bonos | AD15: Otros | AE15: =IFERROR((MONTH(J15)),0) -> 1 | AF15: =IFERROR((YEAR(J15)),0) -> 2025
A16: 12316 | B16: Intereses Financieros a Cobrar LP - PYG | C16: TU FINANCIERA SAECA | D16: Intereses | E16: Activo | F16: No aplica a grupos | H16: AA8063 | I16: 45013 | J16: 45659 | K16: A-py Estable | L16: CDA | M16: 0.098 | N16: =IF(AND(M16>#REF!,Cartera!O3105="Guaraníes"),"Rendimiento significativo",IF(AND(M16>#REF!,Cartera!O3105="Dólares americanos"),"Rendimiento significativo","Rendimiento no significativo")) -> #REF! | O16: Guaraníes | P16: 4310993 | Q16: =IF(O16="Guaraníes",P16,P16*#REF!) -> 4310993 | R16: =IF(O16="Guaraníes",P16/#REF!,P16) -> #REF! | S16: Pendiente | AC16: =IF(ISNUMBER(SEARCH("Acciones",L16)),"Acciones",IF(ISNUMBER(SEARCH("Bono",L16)),"Bonos",IF(ISNUMBER(SEARCH("CDA",L16)),"CDA",IF(ISNUMBER(SEARCH("Fondo",L16)),"Fondo",0)))) -> CDA | AD16: Otros | AE16: =IFERROR((MONTH(J16)),0) -> 1 | AF16: =IFERROR((YEAR(J16)),0) -> 2025
A17: 12316 | B17: Intereses Financieros a Cobrar LP - PYG | C17: SOLAR BANCO S.A.E. | D17: Intereses | E17: Activo | F17: No aplica a grupos | H17: 1093 | J17: 45667 | K17: Apy Estable | L17: CDA | M17: 0.065 | N17: =IF(AND(M17>#REF!,Cartera!O2944="Guaraníes"),"Rendimiento significativo",IF(AND(M17>#REF!,Cartera!O2944="Dólares americanos"),"Rendimiento significativo","Rendimiento no significativo")) -> #REF! | O17: Guaraníes | P17: 3134247 | Q17: =IF(O17="Guaraníes",P17,P17*#REF!) -> 3134247 | R17: =IF(O17="Guaraníes",P17/#REF!,P17) -> #REF! | S17: Pendiente | V17: 3134247 | W17: 13/17 | AC17: =IF(ISNUMBER(SEARCH("Acciones",L17)),"Acciones",IF(ISNUMBER(SEARCH("Bono",L17)),"Bonos",IF(ISNUMBER(SEARCH("CDA",L17)),"CDA",IF(ISNUMBER(SEARCH("Fondo",L17)),"Fondo",0)))) -> CDA | AD17: Otros | AE17: =IFERROR((MONTH(J17)),0) -> 1 | AF17: =IFERROR((YEAR(J17)),0) -> 2025
A18: 12315 | B18: Intereses Financieros a Cobrar LP - USD | C18: BANCO RIO SAECA | D18: Intereses | E18: Activo | F18: No aplica a grupos | H18: UH1802 | I18: 45393 | J18: 45669 | K18: A+py Estable | L18: CDA | M18: 0.055 | N18: =IF(AND(M18>#REF!,Cartera!O3574="Guaraníes"),"Rendimiento significativo",IF(AND(M18>#REF!,Cartera!O3574="Dólares americanos"),"Rendimiento significativo","Rendimiento no significativo")) -> #REF! | O18: Dólares americanos | P18: 291.12 | Q18: =IF(O18="Guaraníes",P18,P18*#REF!) -> #REF! | R18: =IF(O18="Guaraníes",P18/#REF!,P18) -> 291.12 | S18: Pendiente | AC18: =IF(ISNUMBER(SEARCH("Acciones",L18)),"Acciones",IF(ISNUMBER(SEARCH("Bono",L18)),"Bonos",IF(ISNUMBER(SEARCH("CDA",L18)),"CDA",IF(ISNUMBER(SEARCH("Fondo",L18)),"Fondo",0)))) -> CDA | AD18: Otros | AE18: =IFERROR((MONTH(J18)),0) -> 1 | AF18: =IFERROR((YEAR(J18)),0) -> 2025
A19: 12315 | B19: Intereses Financieros a Cobrar LP - USD | C19: ENEX PARAGUAY S.A.E. | D19: Intereses | E19: Activo | F19: No aplica a grupos | G19: BASA CBSA | H19: PYENE01F2836 | J19: 45673 | K19: AA+py Estable | L19: Bonos | M19: 0.06 | N19: =IF(AND(M19>#REF!,Cartera!O263="Guaraníes"),"Rendimiento significativo",IF(AND(M19>#REF!,Cartera!O263="Dólares americanos"),"Rendimiento significativo","Rendimiento no significativo")) -> #REF! | O19: Dólares americanos | P19: 747.9452 | Q19: =IF(O19="Guaraníes",P19,P19*#REF!) -> #REF! | R19: =IF(O19="Guaraníes",P19/#REF!,P19) -> 747.9452 | S19: Pendiente | T19: 10834 | W19: 12/28 | X19: 0 | Y19: 0 | Z19: 14.958904 | AA19: 50 | AB19: 747.9452 | AC19: =IF(ISNUMBER(SEARCH("Acciones",L19)),"Acciones",IF(ISNUMBER(SEARCH("Bono",L19)),"Bonos",IF(ISNUMBER(SEARCH("CDA",L19)),"CDA",IF(ISNUMBER(SEARCH("Fondo",L19)),"Fondo",0)))) -> Bonos | AD19: Otros | AE19: =IFERROR((MONTH(J19)),0) -> 1 | AF19: =IFERROR((YEAR(J19)),0) -> 2025
A20: 12315 | B20: Intereses Financieros a Cobrar LP - USD | C20: UENO HOLDING S.A.E.C.A. | D20: Intereses | E20: Activo | F20: Grupo Vazquez | G20: PUENTE CBSA | H20: PYLCR05F9125 | J20: 45673 | K20: pyBBB + Sensible (-) | L20: Bonos | M20: 0.08 | N20: =IF(AND(M20>#REF!,Cartera!O1864="Guaraníes"),"Rendimiento significativo",IF(AND(M20>#REF!,Cartera!O1864="Dólares americanos"),"Rendimiento significativo","Rendimiento no significativo")) -> #REF! | O20: Dólares americanos | P20: 299.17808 | Q20: =IF(O20="Guaraníes",P20,P20*#REF!) -> #REF! | R20: =IF(O20="Guaraníes",P20/#REF!,P20) -> 299.17808 | S20: Pendiente | T20: 3253 | W20: / | X20: 0 | Y20: 0 | Z20: 19.945205 | AA20: 15 | AB20: 299.17807 | AC20: =IF(ISNUMBER(SEARCH("Acciones",L20)),"Acciones",IF(ISNUMBER(SEARCH("Bono",L20)),"Bonos",IF(ISNUMBER(SEARCH("CDA",L20)),"CDA",IF(ISNUMBER(SEARCH("Fondo",L20)),"Fondo",0)))) -> Bonos | AD20: Otros | AE20: =IFERROR((MONTH(J20)),0) -> 1 | AF20: =IFERROR((YEAR(J20)),0) -> 2025
A21: 12316 | B21: Intereses Financieros a Cobrar LP - PYG | C21: SUDAMERIS BANK S.A.E.C.A. | D21: Intereses | E21: Activo | F21: Grupo Sudameris | H21: 86 | I21: 45043 | J21: 45673 | K21: AA+py Estable | L21: CDA | M21: 0.09 | N21: =IF(AND(M21>#REF!,Cartera!O3186="Guaraníes"),"Rendimiento significativo",IF(AND(M21>#REF!,Cartera!O3186="Dólares americanos"),"Rendimiento significativo","Rendimiento no significativo")) -> #REF! | O21: Guaraníes | P21: 11095890 | Q21: =IF(O21="Guaraníes",P21,P21*#REF!) -> 11095890 | R21: =IF(O21="Guaraníes",P21/#REF!,P21) -> #REF! | S21: Pendiente | AC21: =IF(ISNUMBER(SEARCH("Acciones",L21)),"Acciones",IF(ISNUMBER(SEARCH("Bono",L21)),"Bonos",IF(ISNUMBER(SEARCH("CDA",L21)),"CDA",IF(ISNUMBER(SEARCH("Fondo",L21)),"Fondo",0)))) -> CDA | AD21: Otros | AE21: =IFERROR((MONTH(J21)),0) -> 1 | AF21: =IFERROR((YEAR(J21)),0) -> 2025
A22: 12316 | B22: Intereses Financieros a Cobrar LP - PYG | C22: FINANCIERA PARAGUAYO JAPONESA S.A.E.C.A. | D22: Intereses | E22: Activo | F22: No aplica a grupos | H22: AB 6272 | I22: 45404 | J22: 45674 | K22: A-py Fuerte (+) | L22: CDA | M22: 0.085 | N22: =IF(AND(M22>#REF!,Cartera!O3588="Guaraníes"),"Rendimiento significativo",IF(AND(M22>#REF!,Cartera!O3588="Dólares americanos"),"Rendimiento significativo","Rendimiento no significativo")) -> #REF! | O22: Guaraníes | P22: 4191781 | Q22: =IF(O22="Guaraníes",P22,P22*#REF!) -> 4191781 | R22: =IF(O22="Guaraníes",P22/#REF!,P22) -> #REF! | S22: Pendiente | AC22: =IF(ISNUMBER(SEARCH("Acciones",L22)),"Acciones",IF(ISNUMBER(SEARCH("Bono",L22)),"Bonos",IF(ISNUMBER(SEARCH("CDA",L22)),"CDA",IF(ISNUMBER(SEARCH("Fondo",L22)),"Fondo",0)))) -> CDA | AD22: Otros | AE22: =IFERROR((MONTH(J22)),0) -> 1 | AF22: =IFERROR((YEAR(J22)),0) -> 2025
A23: 12315 | B23: Intereses Financieros a Cobrar LP - USD | C23: BANCO BASA S.A. | D23: Intereses | E23: Activo | F23: Grupo Cartes | G23: CAPITAL MARKETS CBSA | H23: PYBAM01F9268 | J23: 45677 | K23: AA-py Estable | L23: Bonos Subordinados | M23: 0.0525 | N23: =IF(AND(M23>#REF!,Cartera!O1133="Guaraníes"),"Rendimiento significativo",IF(AND(M23>#REF!,Cartera!O1133="Dólares americanos"),"Rendimiento significativo","Rendimiento no significativo")) -> #REF! | O23: Dólares americanos | P23: 174.52055 | Q23: =IF(O23="Guaraníes",P23,P23*#REF!) -> #REF! | R23: =IF(O23="Guaraníes",P23/#REF!,P23) -> 174.52055 | S23: Pendiente | T23: 4 | W23: 4/24 | X23: 0 | Y23: 0 | Z23: 17.452055 | AA23: 10 | AB23: 174.52055 | AC23: =IF(ISNUMBER(SEARCH("Acciones",L23)),"Acciones",IF(ISNUMBER(SEARCH("Bono",L23)),"Bonos",IF(ISNUMBER(SEARCH("CDA",L23)),"CDA",IF(ISNUMBER(SEARCH("Fondo",L23)),"Fondo",0)))) -> Bonos | AD23: Otros | AE23: =IFERROR((MONTH(J23)),0) -> 1 | AF23: =IFERROR((YEAR(J23)),0) -> 2025
A24: 12315 | B24: Intereses Financieros a Cobrar LP - USD | C24: BANCO BASA S.A. | D24: Intereses | E24: Activo | F24: Grupo Cartes | G24: BASA CBSA | H24: PYBAM01F9268 | J24: 45677 | K24: AA-py Estable | L24: Bonos Subordinados | M24: 0.07 | N24: =IF(AND(M24>#REF!,Cartera!O3111="Guaraníes"),"Rendimiento significativo",IF(AND(M24>#REF!,Cartera!O3111="Dólares americanos"),"Rendimiento significativo","Rendimiento no significativo")) -> #REF! | O24: Dólares americanos | P24: 872.6 | Q24: =IF(O24="Guaraníes",P24,P24*#REF!) -> #REF! | R24: =IF(O24="Guaraníes",P24/#REF!,P24) -> 872.6 | S24: Pendiente | T24: 10834 | AC24: =IF(ISNUMBER(SEARCH("Acciones",L24)),"Acciones",IF(ISNUMBER(SEARCH("Bono",L24)),"Bonos",IF(ISNUMBER(SEARCH("CDA",L24)),"CDA",IF(ISNUMBER(SEARCH("Fondo",L24)),"Fondo",0)))) -> Bonos | AD24: Otros | AE24: =IFERROR((MONTH(J24)),0) -> 1 | AF24: =IFERROR((YEAR(J24)),0) -> 2025
A25: 12302 | B25: Inversiones en Bonos LP - USD | C25: CEMENTOS CONCEPCIÓN SOCIEDAD ANÓNIMA EMISORA | D25: Capital | E25: Activo | F25: Grupo Cartes | G25: ASU CAPITAL CBSA | H25: PYCEC01F3409 | I25: 44680 | J25: 46864 | K25: pyAA- Estable | L25: Bonos | M25: 0.06 | N25: =IF(AND(M25>#REF!,Cartera!O25="Guaraníes"),"Rendimiento significativo",IF(AND(M25>#REF!,Cartera!O25="Dólares americanos"),"Rendimiento significativo","Rendimiento no significativo")) -> #REF! | O25: Dólares americanos | P25: 50000 | Q25: =IF(O25="Guaraníes",P25,P25*#REF!) -> #REF! | R25: =IF(O25="Guaraníes",P25/#REF!,P25) -> 50000 | S25: Pendiente | T25: 17035 | V25: 14.96 | AA25: 50 | AC25: =IF(ISNUMBER(SEARCH("Acciones",L25)),"Acciones",IF(ISNUMBER(SEARCH("Bono",L25)),"Bonos",IF(ISNUMBER(SEARCH("CDA",L25)),"CDA",IF(ISNUMBER(SEARCH("Fondo",L25)),"Fondo",0)))) -> Bonos | AD25: Otros | AE25: =IFERROR((MONTH(J25)),0) -> 4 | AF25: =IFERROR((YEAR(J25)),0) -> 2028
A26: Vencido | Cobrado | B26: Vencido | Cobrado | C26: MINISTERIO DE HACIENDA | D26: Intereses | E26: Vencido | Cobrado | F26: Instrumentos Públicos | G26: ASU CAPITAL CBSA | H26: PYTNA01F8541 | I26: 44691 | J26: 44732 | K26: Bonos del Tesoro | L26: Bonos del Tesoro | M26: 0.0775 | N26: =IF(AND(M26>#REF!,Cartera!O26="Guaraníes"),"Rendimiento significativo",IF(AND(M26>#REF!,Cartera!O26="Dólares americanos"),"Rendimiento significativo","Rendimiento no significativo")) -> #REF! | O26: Guaraníes | P26: 11625000 | Q26: =IF(O26="Guaraníes",P26,P26*#REF!) -> 11625000 | R26: =IF(O26="Guaraníes",P26/#REF!,P26) -> #REF! | S26: Acreditado | V26: 38750 | AA26: 300 | AC26: =IF(ISNUMBER(SEARCH("Acciones",L26)),"Acciones",IF(ISNUMBER(SEARCH("Bono",L26)),"Bonos",IF(ISNUMBER(SEARCH("CDA",L26)),"CDA",IF(ISNUMBER(SEARCH("Fondo",L26)),"Fondo",0)))) -> Bonos | AD26: Otros | AE26: =IFERROR((MONTH(J26)),0) -> 6 | AF26: =IFERROR((YEAR(J26)),0) -> 2022
A27: Vencido | Cobrado | B27: Vencido | Cobrado | C27: MINISTERIO DE HACIENDA | D27: Intereses | E27: Vencido | Cobrado | F27: Instrumentos Públicos | G27: ASU CAPITAL CBSA | H27: PYTNA01F8541 | I27: 44691 | J27: 44915 | K27: Bonos del Tesoro | L27: Bonos del Tesoro | M27: 0.0775 | N27: =IF(AND(M27>#REF!,Cartera!O27="Guaraníes"),"Rendimiento significativo",IF(AND(M27>#REF!,Cartera!O27="Dólares americanos"),"Rendimiento significativo","Rendimiento no significativo")) -> #REF! | O27: Guaraníes | P27: 11625000 | Q27: =IF(O27="Guaraníes",P27,P27*#REF!) -> 11625000 | R27: =IF(O27="Guaraníes",P27/#REF!,P27) -> #REF! | S27: Acreditado | V27: 38750 | AA27: 300 | AC27: =IF(ISNUMBER(SEARCH("Acciones",L27)),"Acciones",IF(ISNUMBER(SEARCH("Bono",L27)),"Bonos",IF(ISNUMBER(SEARCH("CDA",L27)),"CDA",IF(ISNUMBER(SEARCH("Fondo",L27)),"Fondo",0)))) -> Bonos | AD27: Otros | AE27: =IFERROR((MONTH(J27)),0) -> 12 | AF27: =IFERROR((YEAR(J27)),0) -> 2022
A28: Vencido | Cobrado | B28: Vencido | Cobrado | C28: MINISTERIO DE HACIENDA | D28: Intereses | E28: Vencido | Cobrado | F28: Instrumentos Públicos | G28: ASU CAPITAL CBSA | H28: PYTNA01F8541 | I28: 44691 | J28: 45097 | K28: Bonos del Tesoro | L28: Bonos del Tesoro | M28: 0.0775 | N28: =IF(AND(M28>#REF!,Cartera!O28="Guaraníes"),"Rendimiento significativo",IF(AND(M28>#REF!,Cartera!O28="Dólares americanos"),"Rendimiento significativo","Rendimiento no significativo")) -> #REF! | O28: Guaraníes | P28: 11625000 | Q28: =IF(O28="Guaraníes",P28,P28*#REF!) -> 11625000 | R28: =IF(O28="Guaraníes",P28/#REF!,P28) -> #REF! | S28: Acreditado | V28: 38750 | AA28: 300 | AC28: =IF(ISNUMBER(SEARCH("Acciones",L28)),"Acciones",IF(ISNUMBER(SEARCH("Bono",L28)),"Bonos",IF(ISNUMBER(SEARCH("CDA",L28)),"CDA",IF(ISNUMBER(SEARCH("Fondo",L28)),"Fondo",0)))) -> Bonos | AD28: Otros | AE28: =IFERROR((MONTH(J28)),0) -> 6 | AF28: =IFERROR((YEAR(J28)),0) -> 2023
A29: Vencido | Cobrado | B29: Vencido | Cobrado | C29: MINISTERIO DE HACIENDA | D29: Intereses | E29: Vencido | Cobrado | F29: Instrumentos Públicos | G29: ASU CAPITAL CBSA | H29: PYTNA01F8541 | I29: 44691 | J29: 45280 | K29: Bonos del Tesoro | L29: Bonos del Tesoro | M29: 0.0775 | N29: =IF(AND(M29>#REF!,Cartera!O29="Guaraníes"),"Rendimiento significativo",IF(AND(M29>#REF!,Cartera!O29="Dólares americanos"),"Rendimiento significativo","Rendimiento no significativo")) -> #REF! | O29: Guaraníes | P29: 11625000 | Q29: =IF(O29="Guaraníes",P29,P29*#REF!) -> 11625000 | R29: =IF(O29="Guaraníes",P29/#REF!,P29) -> #REF! | S29: Acreditado | V29: 38750 | AA29: 300 | AC29: =IF(ISNUMBER(SEARCH("Acciones",L29)),"Acciones",IF(ISNUMBER(SEARCH("Bono",L29)),"Bonos",IF(ISNUMBER(SEARCH("CDA",L29)),"CDA",IF(ISNUMBER(SEARCH("Fondo",L29)),"Fondo",0)))) -> Bonos | AD29: Otros | AE29: =IFERROR((MONTH(J29)),0) -> 12 | AF29: =IFERROR((YEAR(J29)),0) -> 2023
A30: Vencido | Cobrado | B30: Vencido | Cobrado | C30: MINISTERIO DE HACIENDA | D30: Intereses | E30: Vencido | Cobrado | F30: Instrumentos Públicos | G30: ASU CAPITAL CBSA | H30: PYTNA01F8541 | I30: 44691 | J30: 45463 | K30: Bonos del Tesoro | L30: Bonos del Tesoro | M30: 0.0775 | N30: =IF(AND(M30>#REF!,Cartera!O30="Guaraníes"),"Rendimiento significativo",IF(AND(M30>#REF!,Cartera!O30="Dólares americanos"),"Rendimiento significativo","Rendimiento no significativo")) -> #REF! | O30: Guaraníes | P30: 11625000 | Q30: =IF(O30="Guaraníes",P30,P30*#REF!) -> 11625000 | R30: =IF(O30="Guaraníes",P30/#REF!,P30) -> #REF! | S30: Acreditado | V30: 38750 | AA30: 300 | AC30: =IF(ISNUMBER(SEARCH("Acciones",L30)),"Acciones",IF(ISNUMBER(SEARCH("Bono",L30)),"Bonos",IF(ISNUMBER(SEARCH("CDA",L30)),"CDA",IF(ISNUMBER(SEARCH("Fondo",L30)),"Fondo",0)))) -> Bonos | AD30: Otros | AE30: =IFERROR((MONTH(J30)),0) -> 6 | AF30: =IFERROR((YEAR(J30)),0) -> 2024
A31: Vencido | Cobrado | B31: Vencido | Cobrado | C31: BANCO FAMILIAR S.A.E.C.A. | D31: Intereses | E31: Vencido | Cobrado | F31: No aplica a grupos | G31: FAMILIAR CBSA | H31: PYFAM10F6756 | I31: 45266 | J31: 45630 | K31: A+py Estable | L31: Bonos Financieros | M31: 0.0795 | N31: =IF(AND(M31>#REF!,Cartera!O3523="Guaraníes"),"Rendimiento significativo",IF(AND(M31>#REF!,Cartera!O3523="Dólares americanos"),"Rendimiento significativo","Rendimiento no significativo")) -> #REF! | O31: Guaraníes | P31: 1982054.8 | Q31: =IF(O31="Guaraníes",P31,P31*#REF!) -> 1982054.8 | R31: =IF(O31="Guaraníes",P31/#REF!,P31) -> #REF! | S31: Acreditado | T31: 26543 | AC31: =IF(ISNUMBER(SEARCH("Acciones",L31)),"Acciones",IF(ISNUMBER(SEARCH("Bono",L31)),"Bonos",IF(ISNUMBER(SEARCH("CDA",L31)),"CDA",IF(ISNUMBER(SEARCH("Fondo",L31)),"Fondo",0)))) -> Bonos | AD31: Otros | AE31: =IFERROR((MONTH(J31)),0) -> 12 | AF31: =IFERROR((YEAR(J31)),0) -> 2024
A32: 12301 | B32: Inversiones en Bonos LP - PYG | C32: MINISTERIO DE HACIENDA | D32: Capital | E32: Activo | F32: Instrumentos Públicos | G32: ASU CAPITAL CBSA | H32: PYTNA01F8541 | I32: 44691 | J32: 45828 | K32: Bonos del Tesoro | L32: Bonos del Tesoro | M32: 0.0775 | N32: =IF(AND(M32>#REF!,Cartera!O32="Guaraníes"),"Rendimiento significativo",IF(AND(M32>#REF!,Cartera!O32="Dólares americanos"),"Rendimiento significativo","Rendimiento no significativo")) -> #REF! | O32: Guaraníes | P32: 300000000 | Q32: =IF(O32="Guaraníes",P32,P32*#REF!) -> 300000000 | R32: =IF(O32="Guaraníes",P32/#REF!,P32) -> #REF! | S32: Pendiente | V32: 38750 | AA32: 300 | AC32: =IF(ISNUMBER(SEARCH("Acciones",L32)),"Acciones",IF(ISNUMBER(SEARCH("Bono",L32)),"Bonos",IF(ISNUMBER(SEARCH("CDA",L32)),"CDA",IF(ISNUMBER(SEARCH("Fondo",L32)),"Fondo",0)))) -> Bonos | AD32: Otros | AE32: =IFERROR((MONTH(J32)),0) -> 6 | AF32: =IFERROR((YEAR(J32)),0) -> 2025
A33: Vencido | Cobrado | B33: Vencido | Cobrado | C33: BANCO BASA S.A. | D33: Intereses | E33: Vencido | Cobrado | F33: Grupo Cartes | G33: ASU CAPITAL CBSA | H33: PYBAM02F3500 | I33: 44704 | J33: 44795 | K33: AA-py Estable | L33: Bonos | M33: 0.06 | N33: =IF(AND(M33>#REF!,Cartera!O33="Guaraníes"),"Rendimiento significativo",IF(AND(M33>#REF!,Cartera!O33="Dólares americanos"),"Rendimiento significativo","Rendimiento no significativo")) -> #REF! | O33: Dólares americanos | P33: 373.9726 | Q33: =IF(O33="Guaraníes",P33,P33*#REF!) -> #REF! | R33: =IF(O33="Guaraníes",P33/#REF!,P33) -> 373.9726 | S33: Acreditado | V33: 14.958904 | AA33: 25 | AC33: =IF(ISNUMBER(SEARCH("Acciones",L33)),"Acciones",IF(ISNUMBER(SEARCH("Bono",L33)),"Bonos",IF(ISNUMBER(SEARCH("CDA",L33)),"CDA",IF(ISNUMBER(SEARCH("Fondo",L33)),"Fondo",0)))) -> Bonos | AD33: Otros | AE33: =IFERROR((MONTH(J33)),0) -> 8 | AF33: =IFERROR((YEAR(J33)),0) -> 2022
A34: Vencido | Cobrado | B34: Vencido | Cobrado | C34: BANCO BASA S.A. | D34: Intereses | E34: Vencido | Cobrado | F34: Grupo Cartes | G34: ASU CAPITAL CBSA | H34: PYBAM02F3500 | I34: 44704 | J34: 44886 | K34: AA-py Estable | L34: Bonos | M34: 0.06 | N34: =IF(AND(M34>#REF!,Cartera!O34="Guaraníes"),"Rendimiento significativo",IF(AND(M34>#REF!,Cartera!O34="Dólares americanos"),"Rendimiento significativo","Rendimiento no significativo")) -> #REF! | O34: Dólares americanos | P34: 373.9726 | Q34: =IF(O34="Guaraníes",P34,P34*#REF!) -> #REF! | R34: =IF(O34="Guaraníes",P34/#REF!,P34) -> 373.9726 | S34: Acreditado | V34: 14.958904 | AA34: 25 | AC34: =IF(ISNUMBER(SEARCH("Acciones",L34)),"Acciones",IF(ISNUMBER(SEARCH("Bono",L34)),"Bonos",IF(ISNUMBER(SEARCH("CDA",L34)),"CDA",IF(ISNUMBER(SEARCH("Fondo",L34)),"Fondo",0)))) -> Bonos | AD34: Otros | AE34: =IFERROR((MONTH(J34)),0) -> 11 | AF34: =IFERROR((YEAR(J34)),0) -> 2022
A35: Vencido | Cobrado | B35: Vencido | Cobrado | C35: BANCO BASA S.A. | D35: Intereses | E35: Vencido | Cobrado | F35: Grupo Cartes | G35: ASU CAPITAL CBSA | H35: PYBAM02F3500 | I35: 44704 | J35: 44977 | K35: AA-py Estable | L35: Bonos | M35: 0.06 | N35: =IF(AND(M35>#REF!,Cartera!O35="Guaraníes"),"Rendimiento significativo",IF(AND(M35>#REF!,Cartera!O35="Dólares americanos"),"Rendimiento significativo","Rendimiento no significativo")) -> #REF! | O35: Dólares americanos | P35: 373.9726 | Q35: =IF(O35="Guaraníes",P35,P35*#REF!) -> #REF! | R35: =IF(O35="Guaraníes",P35/#REF!,P35) -> 373.9726 | S35: Acreditado | V35: 14.958904 | AA35: 25 | AC35: =IF(ISNUMBER(SEARCH("Acciones",L35)),"Acciones",IF(ISNUMBER(SEARCH("Bono",L35)),"Bonos",IF(ISNUMBER(SEARCH("CDA",L35)),"CDA",IF(ISNUMBER(SEARCH("Fondo",L35)),"Fondo",0)))) -> Bonos | AD35: Otros | AE35: =IFERROR((MONTH(J35)),0) -> 2 | AF35: =IFERROR((YEAR(J35)),0) -> 2023
A36: Vencido | Cobrado | B36: Vencido | Cobrado | C36: BANCO BASA S.A. | D36: Intereses | E36: Vencido | Cobrado | F36: Grupo Cartes | G36: ASU CAPITAL CBSA | H36: PYBAM02F3500 | I36: 44704 | J36: 45068 | K36: AA-py Estable | L36: Bonos | M36: 0.06 | N36: =IF(AND(M36>#REF!,Cartera!O36="Guaraníes"),"Rendimiento significativo",IF(AND(M36>#REF!,Cartera!O36="Dólares americanos"),"Rendimiento significativo","Rendimiento no significativo")) -> #REF! | O36: Dólares americanos | P36: 373.9726 | Q36: =IF(O36="Guaraníes",P36,P36*#REF!) -> #REF! | R36: =IF(O36="Guaraníes",P36/#REF!,P36) -> 373.9726 | S36: Acreditado | V36: 14.958904 | AA36: 25 | AC36: =IF(ISNUMBER(SEARCH("Acciones",L36)),"Acciones",IF(ISNUMBER(SEARCH("Bono",L36)),"Bonos",IF(ISNUMBER(SEARCH("CDA",L36)),"CDA",IF(ISNUMBER(SEARCH("Fondo",L36)),"Fondo",0)))) -> Bonos | AD36: Otros | AE36: =IFERROR((MONTH(J36)),0) -> 5 | AF36: =IFERROR((YEAR(J36)),0) -> 2023
A37: Vencido | Cobrado | B37: Vencido | Cobrado | C37: BANCO BASA S.A. | D37: Intereses | E37: Vencido | Cobrado | F37: Grupo Cartes | G37: ASU CAPITAL CBSA | H37: PYBAM02F3500 | I37: 44704 | J37: 45159 | K37: AA-py Estable | L37: Bonos | M37: 0.06 | N37: =IF(AND(M37>#REF!,Cartera!O37="Guaraníes"),"Rendimiento significativo",IF(AND(M37>#REF!,Cartera!O37="Dólares americanos"),"Rendimiento significativo","Rendimiento no significativo")) -> #REF! | O37: Dólares americanos | P37: 373.9726 | Q37: =IF(O37="Guaraníes",P37,P37*#REF!) -> #REF! | R37: =IF(O37="Guaraníes",P37/#REF!,P37) -> 373.9726 | S37: Acreditado | V37: 14.958904 | AA37: 25 | AC37: =IF(ISNUMBER(SEARCH("Acciones",L37)),"Acciones",IF(ISNUMBER(SEARCH("Bono",L37)),"Bonos",IF(ISNUMBER(SEARCH("CDA",L37)),"CDA",IF(ISNUMBER(SEARCH("Fondo",L37)),"Fondo",0)))) -> Bonos | AD37: Otros | AE37: =IFERROR((MONTH(J37)),0) -> 8 | AF37: =IFERROR((YEAR(J37)),0) -> 2023
A38: Vencido | Cobrado | B38: Vencido | Cobrado | C38: BANCO BASA S.A. | D38: Intereses | E38: Vencido | Cobrado | F38: Grupo Cartes | G38: ASU CAPITAL CBSA | H38: PYBAM02F3500 | I38: 44704 | J38: 45250 | K38: AA-py Estable | L38: Bonos | M38: 0.06 | N38: =IF(AND(M38>#REF!,Cartera!O38="Guaraníes"),"Rendimiento significativo",IF(AND(M38>#REF!,Cartera!O38="Dólares americanos"),"Rendimiento significativo","Rendimiento no significativo")) -> #REF! | O38: Dólares americanos | P38: 373.9726 | Q38: =IF(O38="Guaraníes",P38,P38*#REF!) -> #REF! | R38: =IF(O38="Guaraníes",P38/#REF!,P38) -> 373.9726 | S38: Acreditado | V38: 14.958904 | AA38: 25 | AC38: =IF(ISNUMBER(SEARCH("Acciones",L38)),"Acciones",IF(ISNUMBER(SEARCH("Bono",L38)),"Bonos",IF(ISNUMBER(SEARCH("CDA",L38)),"CDA",IF(ISNUMBER(SEARCH("Fondo",L38)),"Fondo",0)))) -> Bonos | AD38: Otros | AE38: =IFERROR((MONTH(J38)),0) -> 11 | AF38: =IFERROR((YEAR(J38)),0) -> 2023
A39: Vencido | Cobrado | B39: Vencido | Cobrado | C39: BANCO BASA S.A. | D39: Intereses | E39: Vencido | Cobrado | F39: Grupo Cartes | G39: ASU CAPITAL CBSA | H39: PYBAM02F3500 | I39: 44704 | J39: 45341 | K39: AA-py Estable | L39: Bonos | M39: 0.06 | N39: =IF(AND(M39>#REF!,Cartera!O39="Guaraníes"),"Rendimiento significativo",IF(AND(M39>#REF!,Cartera!O39="Dólares americanos"),"Rendimiento significativo","Rendimiento no significativo")) -> #REF! | O39: Dólares americanos | P39: 373.9726 | Q39: =IF(O39="Guaraníes",P39,P39*#REF!) -> #REF! | R39: =IF(O39="Guaraníes",P39/#REF!,P39) -> 373.9726 | S39: Acreditado | V39: 14.958904 | AA39: 25 | AC39: =IF(ISNUMBER(SEARCH("Acciones",L39)),"Acciones",IF(ISNUMBER(SEARCH("Bono",L39)),"Bonos",IF(ISNUMBER(SEARCH("CDA",L39)),"CDA",IF(ISNUMBER(SEARCH("Fondo",L39)),"Fondo",0)))) -> Bonos | AD39: Otros | AE39: =IFERROR((MONTH(J39)),0) -> 2 | AF39: =IFERROR((YEAR(J39)),0) -> 2024
A40: Vencido | Cobrado | B40: Vencido | Cobrado | C40: BANCO BASA S.A. | D40: Intereses | E40: Vencido | Cobrado | F40: Grupo Cartes | G40: ASU CAPITAL CBSA | H40: PYBAM02F3500 | I40: 44704 | J40: 45432 | K40: AA-py Estable | L40: Bonos | M40: 0.06 | N40: =IF(AND(M40>#REF!,Cartera!O40="Guaraníes"),"Rendimiento significativo",IF(AND(M40>#REF!,Cartera!O40="Dólares americanos"),"Rendimiento significativo","Rendimiento no significativo")) -> #REF! | O40: Dólares americanos | P40: 373.9726 | Q40: =IF(O40="Guaraníes",P40,P40*#REF!) -> #REF! | R40: =IF(O40="Guaraníes",P40/#REF!,P40) -> 373.9726 | S40: Acreditado | V40: 14.958904 | AA40: 25 | AC40: =IF(ISNUMBER(SEARCH("Acciones",L40)),"Acciones",IF(ISNUMBER(SEARCH("Bono",L40)),"Bonos",IF(ISNUMBER(SEARCH("CDA",L40)),"CDA",IF(ISNUMBER(SEARCH("Fondo",L40)),"Fondo",0)))) -> Bonos | AD40: Otros | AE40: =IFERROR((MONTH(J40)),0) -> 5 | AF40: =IFERROR((YEAR(J40)),0) -> 2024
...
